Workbook

Sheet TD 29 ABRL
A1: Etiquetas de fila | B1: Cuenta de Respuesta aprobación
A2: 1 | B2: 96
A3: Coordinador General Regional | B3: 1
A4: Coordinador Local Regional | B4: 3
A5: Gestor | B5: 57
A6: Profesional Administrativo y Financiero | B6: 2
A7: Profesional de Alianzas y Conexión a Mercados
A8: Profesional de logística y compra | B8: 6
A9: Profesional de Seguimiento e Información | B9: 1
A10: Profesional Tallerista | B10: 22
A11: Técnico Administrativo Regional de Apoyo | B11: 4
A12: 2 | B12: 51
A13: Gestor | B13: 33
A14: Profesional Administrativo y Financiero | B14: 1
A15: Profesional de Alianzas y Conexión a Mercados | B15: 2
A16: Profesional de logística y compra | B16: 2
A17: Profesional Tallerista | B17: 11
A18: Técnico Administrativo Regional de Apoyo | B18: 2
A19: 3 | B19: 59
A20: Coordinador General Regional | B20: 1
A21: Coordinador Local Regional | B21: 1
A22: Gestor | B22: 33
A23: Profesional Administrativo y Financiero | B23: 1
A24: Profesional de Alianzas y Conexión a Mercados | B24: 1
A25: Profesional de logística y compra | B25: 7
A26: Profesional de Seguimiento e Información | B26: 2
A27: Profesional Tallerista | B27: 9
A28: Técnico Administrativo Regional de Apoyo | B28: 4
A29: 4 | B29: 193
A30: Coordinador General Regional | B30: 2
A31: Coordinador Local Regional | B31: 8
A32: Gestor | B32: 92
A33: Profesional Administrativo y Financiero | B33: 4
A34: Profesional de Alianzas y Conexión a Mercados | B34: 5
A35: Profesional de logística y compra | B35: 17
A36: Profesional de Seguimiento e Información | B36: 6
A37: Profesional Tallerista | B37: 54
A38: Técnico Administrativo Regional de Apoyo | B38: 5
A39: 5 | B39: 107
A40: Coordinador General Regional | B40: 1
...

Sheet Faltantes eq.min
A1: Región | B1: Rol | C1: Cantidad | E1: CANTIDAD MINIMA REQUERIDA CON ADICIÓN
A2: 1 | B2: Profesional alianzas y conexión a mercados | C2: 1 | E2: Rol | F2: Cantidad
A3: 2 | B3: Coordinación General Regional | C3: 1 | E3: Coordinación General Regional - 1 por región | F3: 5
A4: 2 | B4: Coordinador Local Regional | C4: 2 | E4: Coordinadores locales regionales (2 por región) | F4: 10
A5: 2 | B5: Profesional de Logística y compra | C5: 3 | E5: Gestores | F5: =165+18 -> 183
A6: 2 | B6: Profesional de seguimiento e información | C6: 1 | E6: Profesional Administrativo y Financiero - 1 por región | F6: 5
A7: 2 | B7: Técnicos Administrativos regional de Apoyo | C7: 1 | E7: Profesional alianzas y conexión a mercados - 1 por región | F7: 5
A8: 3 | B8: Coordinador Local Regional | C8: 1 | E8: Profesional de Logística y compra - 5 por región | F8: =25+10 -> 35
A9: 5 | B9: Profesional alianzas y conexión a mercados | C9: 1 | E9: Profesional de seguimiento e información - 1 por región | F9: 5
A10: 5 | B10: Profesional de logística y compra | C10: 2 | E10: Profesional tallerista | F10: =65+2 -> 67
E11: Técnicos Administrativos regional de Apoyo - 3 por región | F11: =15+5 -> 20

Sheet Base sin duplicados  
A1: Numero de cedula | B1: Fecha de envio | C1: Nombre completo | D1: Numero de cedula | E1: Cargo | F1: Enlace documentacion | G1: Celular | H1: Región | I1: Departamento | J1: Municipio | K1: Respuesta aprobación | L1: NO aprobados | M1: Fecha de envío a Prosperidad | N1: Aprobación | O1: Equipo Nacional/Regional | P1: Contratado | Q1: Estatus | R1: Observaciones Validación de BD | S1: Validar
B2: 46163 | C2: Fredy Edilberto Moyano Jara | D2: 479844 | E2: PROFESIONAL DE SEGUIMIENTO E INFORMACIÓN | F2: https://drive.google.com/drive/folders/1AdSxOQWHki3W5ThnUvzxoJC6BOdvqwnk?usp=sharing | H2: 4 | K2: RCE_260523_97 | M2: 46165 | N2: SI
A3: 2358332 | B3: 46062 | C3: MARIA LUISA GIL RESTREPO | D3: 2358332 | E3: Profesional Tallerista | F3: https://drive.google.com/drive/folders/1S07Pv3QXyux5CD1bchUhLSo8kCxB_cix?usp=sharing | G3: 3146915795 - 3159046950 | H3: 1 | I3: Atlántico | J3: Barranquilla | K3: RCE_260211_49 | M3: 46072 | N3: Sí | O3: Equipo Técnico Territorial | P3: No | Q3: En Base de Datos
A4: 3119289 | B4: 46032 | C4: HELBERTH YAIR BABATIVA RODRIGUEZ | D4: 3119289 | E4: Gestor | F4: https://drive.google.com/drive/folders/1VNX2dICSN_hTQUckuZtEBm0VlZUdzs5C?usp=sharing | G4: 3112168399- 3108578185 | H4: 2 | I4: Cundinamarca | J4: Villagomez | K4: RCE_260122_28 | M4: 46035 | N4: Sí | O4: Equipo Técnico Territorial | P4: Sí | Q4: Retirado | S4: RCE_260122_28
A5: 3606544 | B5: 46038 | C5: DENNISSE PAOLA TULCÁN PUENTES | D5: 3606544 | E5: Profesional Tallerista | F5: https://drive.google.com/drive/folders/1ZqsfOdsr4T_wj8xuPymkh39bygCXrl5U?usp=sharing | G5: 311 616 2115 | H5: 5 | I5: Cauca | J5: Popayán | K5: RCE_260120_22 | M5: 46043 | N5: Sí | O5: Equipo Técnico Territorial | P5: No | Q5: Retirado | S5: RCE_260120_22
A6: 3829931 | B6: 46133 | C6: Oscar Luis Arias Jaraba | D6: 3829931 | E6: Gestor | F6: https://drive.google.com/drive/folders/1At8XkAr8afuOE1ndQriARlhyWmQXkWAY?usp=sharing | G6: 3135410685 | H6: 1 | I6: Bolívar | J6: El carmen de Bolívar | L6: RCE_260425_86 | N6: No | O6: Equipo Técnico Territorial | P6: No
A7: 4438271 | B7: 46029 | C7: CRISTIAM DAVIS OROZCO DIAZ | D7: 4438271 | E7: Profesional de logística y compra | F7: https://drive.google.com/drive/folders/1Dqrhb2d1twKZQeD01ssGY8C3KHo0wNeC | G7: 3148759309 | H7: 2 | I7: Caldas | J7: #REF! | L7: RCE_260109_12 | M7: 46035 | N7: No | O7: Equipo Nacional | P7: No | Q7: No Aprobado
A8: 4519046 | B8: 46084 | C8: ADRIAN FERNANDO SUAREZ GARTNER | D8: 4519046 | E8: Gestor | F8: https://drive.google.com/drive/folders/1L2LqDJNxeUkDVCQt3wFUjChQ8NIZih6n?usp=sharing | G8: 3045699047 | H8: 2 | I8: Caldas | J8: #REF! | K8: RCE_260304_70 | N8: Sí | O8: Equipo Técnico Territorial | P8: No
B9: 46161 | C9: HECTOR FABIO LONDOÑO GALVIS | D9: 4583948 | E9: GESTOR | F9: https://drive.google.com/drive/folders/1xgQZGQhuuamPYxKsan7XdLi8Z7swPnAe?usp=sharing | G9: 3167984165 - 3167984165 | H9: 2 | K9: RCE_260521_96 | M9: 46163 | N9: SI
A10: 4617197 | B10: 46084 | C10: CHRISTIAN JAVIER QUIÑONES A. | D10: 4617197 | E10: Gestor | F10: https://drive.google.com/drive/folders/13LiyMHiKG3PcFnCeQulhISYolbZa11p7?usp=sharing | G10: 3108702287 | H10: 5 | I10: Cauca | J10: #REF! | K10: RCE_260304_70 | N10: Sí | O10: Equipo Técnico Territorial | P10: No
A11: 5205527 | B11: 46041 | C11: CARLOS ÁNGEL VELÁSQUEZ INCA | D11: 5205527 | E11: Gestor | F11: https://drive.google.com/drive/folders/1734J8L05IXDf81nE90hfvDIKl4m5z7nD?usp=sharing | G11: 318 528 6727 | H11: 5 | I11: Nariño | J11: Chachagüí | K11: RCE_260121_24 | M11: 46049 | N11: Sí | O11: Equipo Técnico Territorial | P11: Sí | Q11: Activo | S11: RCE_260121_24
A12: 5470135 | B12: 46066 | C12: GUSTAVO ALBERTO QUINTANILLA TORRADO | D12: 5470135 | E12: Profesional Tallerista | F12: https://drive.google.com/drive/folders/1CqG5XMOVPmqJ69mzapLAy_VrYRMp5Cuj?usp=sharing | G12: 3153904870 | H12: 3 | I12: Norte de Santander | J12: #REF! | K12: RCE_260217_55 | M12: 46076 | N12: Sí | O12: Equipo Técnico Territorial | P12: NO | Q12: En Base de Datos
A13: 6386946 | B13: 46041 | C13: JUAN JOSE LONDOÑO LONDOÑO | D13: 6386946 | E13: Gestor | F13: https://drive.google.com/drive/folders/1_LnDa0c2aUzFHAA0wbMUxqUmZ5J_p4ZV?usp=sharing | G13: 317 402 1724 | H13: 5 | I13: Valle del Cauca | J13: Palmira | K13: RCE_260122_27 | M13: 46049 | N13: Sí | O13: Equipo Técnico Territorial | P13: Sí | Q13: Activo | S13: RCE_260122_27
A14: 6497712 | B14: 46097 | C14: RUBEN DARIO VILLADA PEREA | D14: 6497712 | E14: Gestor | F14: https://drive.google.com/drive/folders/1dLWfY5LNpeBuLAKfNVq-ck7lwJ3y7zhg?usp=sharing | G14: 3125921087 | H14: 1 | I14: Córdoba | J14: #REF! | K14: RCE_260318_76 | N14: Sí | O14: Equipo Técnico Territorial | P14: No
B15: 46163 | C15: RENGER MONROY PERILLA | D15: 6761893 | E15: PROFESIONAL DE LOGÍSTICA Y COMPRAS | F15: https://drive.google.com/drive/folders/1gT1Q_3bKK-B0IFTipcqObYj-WJ1A8ikj?usp=sharing | H15: 3 | L15: RCE_260523_98 | M15: 46165 | N15: NO
A16: 6776982 | B16: 46045 | C16: EDGAR ARTURO PRIETO ACEVEDO | D16: 6776982 | E16: Gestor | F16: https://drive.google.com/drive/folders/12cAy1pgg7lOCIlgQi4av7cqL5zjGFY78?usp=sharing | G16: 3165282333 | H16: 3 | I16: Boyacá | J16: Chivata | K16: RCE_260126_31 | M16: 46049 | N16: Sí | O16: Equipo Técnico Territorial | P16: Sí | Q16: Activo | S16: RCE_260126_31
A17: 6804699 | B17: 46056 | C17: Mauricio Montenegro Perafan | D17: 6804699 | E17: Gestor | F17: https://drive.google.com/drive/folders/1WBOyRIImocIit8THEQDqreQHZtd0oHvJ?usp=sharing | G17: 3156045259 | H17: 4 | I17: Caquetá | J17: Florencia | K17: RCE_260205_41 | M17: 46062 | N17: Sí | O17: Equipo Técnico Territorial | P17: Sí | Q17: Activo
A18: 6870817 | B18: 46032 | C18: EMEL FRANCISCO CONSTANTE ORTEGA | D18: 6870817 | E18: Gestor | F18: https://drive.google.com/drive/folders/1N8qkQSGKhSyFRt9jURH5KPNbEQP3LwMj?usp=sharing | G18: 3215879724, 3016571863 | H18: 1 | I18: Cesar | J18: Valledupar | K18: RCE_260115_17 RCE_260121_24 | M18: 46049 | N18: Sí | O18: Equipo Técnico Territorial | P18: Sí | Q18: Activo | R18: Cambio de Rol | S18: RCE_260116_18
A19: 7095172 | B19: 46045 | C19: Juan Pablo Leal Riveros | D19: 7095172 | E19: Gestor | F19: https://drive.google.com/drive/folders/1sm88e_nw6wXliZuHbc16pqoSE_-d6GHS?usp=sharing | G19: 3104401589 | H19: 2 | I19: Bogotá | J19: Bogotá | K19: RCE_260127_33 | M19: 46062 | N19: Sí | O19: Equipo Técnico Territorial | P19: Sí | Q19: Activo | S19: RCE_260127_33
A20: 7253321 | B20: 46041 | C20: MAURO FABIAN SALAZAR BUITRAGO | D20: 7253321 | E20: Gestor | F20: https://drive.google.com/drive/folders/1WQ_E4AOWWWipWPGKAEAm0B_MkmQNAsr6?usp=sharing | G20: 320 342 0963 | H20: 3 | I20: Boyacá | J20: Puerto boyacá | K20: RCE_260122_27 | M20: 46049 | N20: Sí | O20: Equipo Técnico Territorial | P20: Sí | Q20: Activo | S20: RCE_260122_27
A21: 7303243 | B21: 46050 | C21: JUAN MANUEL CASTAÑEDA ISAZA | D21: 7303243 | E21: Gestor | F21: https://drive.google.com/drive/folders/1YwvDoQG6sbTocOPwNGMoLIpx9_p5NQmF?usp=sharing | G21: 3118514375 | H21: 4 | I21: Bogotá | J21: Bogotá | K21: RCE_260204_38 | M21: 46062 | N21: Sí | O21: Equipo Técnico Territorial | P21: No | Q21: En Base de Datos
B22: 46163 | C22: DAIRO POZO MURGAS | D22: 7572573 | E22: PROFESIONAL DE SEGUIMIENTO E INFORMACIÓN | F22: https://drive.google.com/drive/folders/11YRmQgybbJZAHo_jiLawi24Mxn8b1fql?usp=sharing | H22: 1 | K22: RCE_260523_97 | M22: 46165 | N22: SI
A23: 7684683 | B23: 46073 | C23: Diego Alfonso Polania Suarez | D23: 7684683 | E23: Gestor | F23: https://drive.google.com/drive/folders/1rTX7qVFVBRnr2Q-VQnX9JFR_COmfgTXU?usp=sharing | G23: 3132251215 | H23: 4 | I23: Huila | J23: Neiva | K23: RCE_260220_57 | M23: 46076 | N23: Sí | O23: Equipo Técnico Territorial | P23: NO | Q23: En Base de Datos
A24: 7688678 | B24: 46073 | C24: LUIS FERNANDO CALDERON ALVARADO | D24: 7688678 | E24: Gestor | F24: https://drive.google.com/drive/folders/1gwM7QVcV97ZHxepTPahQ8VmK0EAO5bp0?usp=sharing | G24: 310311 5927 | H24: 4 | I24: Huila | J24: Neiva | K24: RCE_260220_57 | M24: 46076 | N24: Sí | O24: Equipo Técnico Territorial | P24: NO | Q24: En Base de Datos
A25: 7694230 | B25: 46073 | C25: Alex Nelson Trujillo Pinto | D25: 7694230 | E25: Gestor | F25: https://drive.google.com/drive/folders/1SUTXeGUahWQebcSvArYrL4A1POQWAtDL?usp=sharing | G25: 3158762056 | H25: 4 | I25: Huila | J25: Rivera | K25: RCE_260220_57 | M25: 46076 | N25: Sí | O25: Equipo Técnico Territorial | P25: Sí | Q25: Retirado | R25: Retirado 03/03/2026
A26: 7700268 | B26: 46084 | C26: HÉCTOR GABRIEL ORTIZ SOLANO | D26: 7700268 | E26: Gestor | F26: https://drive.google.com/drive/folders/10IEFd2AbsBruyfyWzOlhYQqf3dTQBwqV?usp=sharing | G26: 8645667-3144710291 | H26: 4 | I26: Huila | J26: #REF! | K26: RCE_260304_70 | N26: Sí | O26: Equipo Técnico Territorial | P26: No
B27: 46161 | C27: LUIS RODRIGO JIMENEZ BOHORQUEZ | D27: 7702118 | E27: PROFESIONAL DE LOGÍSTICA Y COMPRAS | F27: https://drive.google.com/drive/folders/1nRmFrzoeCb8KCg35ByPH2YgTy72O_u4j?usp=sharing | G27: 3105893400-3168731730 | H27: 4 | K27: RCE_260521_96 | M27: 46163 | N27: SI
A28: 7733300 | B28: 46045 | C28: HARVY GENTIL DIAZ SIERRA | D28: 7733300 | E28: Gestor | F28: https://drive.google.com/drive/folders/1pqGrIPvi8rF2VWt1bNhCiAsskOvhqHxQ?usp=sharing | G28: 3127303159 | H28: 5 | I28: Cauca | J28: Timbío | K28: RCE_260126_31 | M28: 46049 | N28: Sí | O28: Equipo Técnico Territorial | P28: Sí | Q28: Activo | S28: RCE_260126_31
A29: 8324104 | B29: 46032 | C29: RAÚL TOMSON SALAS BEYTAR | D29: 8324104 | E29: Gestor | F29: https://drive.google.com/drive/folders/1mijS_f0STcB_ts1hwR62zyZrCiWxk_cn?usp=sharing | G29: 3114399647 | H29: 5 | I29: Antioquia | J29: Apartadó | K29: RCE_260115_17 | M29: 46039 | N29: Sí | O29: Equipo Técnico Territorial | P29: Sí | Q29: Activo | S29: RCE_260115_17
A30: 8641177 | B30: 46032 | C30: MIGUEL EDUARDO OLMOS DE LA ROSA | D30: 8641177 | E30: Gestor | F30: https://drive.google.com/drive/folders/18ek6dQDyIPXEbEx8DbfjCdwIggyrvG7a?usp=sharing | G30: 3004428375 | H30: 1 | I30: Atlántico | J30: Sabanalarga | K30: RCE_260115_17 | M30: 46039 | N30: Sí | O30: Equipo Técnico Territorial | P30: No | Q30: Retirado | S30: RCE_260115_17
A31: 8645647 | B31: 46017 | C31: OSCAR JAVIER POLO CERVANTE | D31: 8645647 | E31: Gestor | F31: https://drive.google.com/drive/folders/1s76KtYpo9xkyKsphjMU_6cY-tYdHchLr?usp=sharing | G31: 3008051714. | H31: 1 | I31: Atlántico | J31: Sabanalarga | K31: RCE_251230_1 | M31: 46035 | N31: Sí | O31: Equipo Técnico Territorial | P31: Sí | Q31: Activo | S31: RCE_251230_1
A32: 8757556 | B32: 46038 | C32: FIDEL NAVARRO GUTIÉRREZ | D32: 8757556 | E32: Profesional Tallerista | F32: https://drive.google.com/drive/folders/1y-iIlpo2Ge6O7a3bUvNNJhG_8iKCUT3P?usp=sharing | G32: 3205660310 | H32: 4 | I32: Bogotá | J32: Bogotá | L32: RCE_260120_21 | M32: 46043 | N32: No | O32: Equipo Técnico Territorial | P32: No | Q32: No Aprobado
A33: 9021076 | B33: 46097 | C33: JESÚS RICARDO MÉNDEZ GAMARRA | D33: 9021076 | E33: Gestor | F33: https://drive.google.com/drive/folders/1Dpaom8thc9xUYc7w8La6o5ByKBWVhXDv?usp=sharing | G33: 3148671578 | H33: 1 | I33: Bolívar | J33: #REF! | K33: RCE_260318_76 | N33: Sí | O33: Equipo Técnico Territorial | P33: No
A34: 9729732 | B34: 46045 | C34: ANDRÉS MAURICIO CAMACHO MONTEALEGRE | D34: 9729732 | E34: Profesional Tallerista | F34: https://drive.google.com/drive/folders/1_kmvYs61oj8yc7yskMMk2DASUB9rgMM3?usp=sharing | G34: 3154125376 | H34: 2 | I34: Tolima | J34: Ibagué | K34: RCE_260126_31 | M34: 46049 | N34: Sí | O34: Equipo Técnico Territorial | P34: No | Q34: Retirado | S34: RCE_260126_31
A35: 10285901 | B35: 46032 | C35: RAFAEL ENRIQUE ARRAZOLA BEDOYA | D35: 10285901 | E35: Gestor | F35: https://drive.google.com/drive/folders/10ZE1mJe7e2AUkuSKh6irra4fygr-MIO_?usp=sharing | G35: 3108544203 | H35: 2 | I35: Risaralda | J35: Pereira | K35: RCE_260115_17 | M35: 46039 | N35: Sí | O35: Equipo Técnico Territorial | P35: No | Q35: Retirado | R35: Renuncia al proceso | S35: RCE_260115_17
A36: 10302261 | B36: 46073 | C36: Hector Julio Serna Valencia | D36: 10302261 | E36: Gestor | F36: https://drive.google.com/drive/folders/1oF9kX3kkg9p1OwP7SSR-Ga-XMD5kEJvN?usp=sharing | G36: 3207473302 | H36: 5 | I36: Cauca | J36: Morales | K36: RCE_260220_57 | M36: 46076 | N36: Sí | O36: Equipo Técnico Territorial | P36: NO | Q36: En Base de Datos
A37: 10307077 | B37: 46017 | C37: JANNER ANDRES PERAFAN SAMBONI | D37: 10307077 | E37: Gestor | F37: https://drive.google.com/drive/folders/1_KdWNmRIUdtCkrNmZtfqdrBsh1NuuudE?usp=sharing | G37: 3217763244 | H37: 5 | I37: Cauca | J37: Popayán | K37: RCE_251230_1 | M37: 46035 | N37: Sí | O37: Equipo Técnico Territorial | P37: Sí | Q37: Activo | S37: RCE_251230_1
A38: 10781720 | B38: 46020 | C38: JAVIER FRANCISCO DURANGO CHICA | D38: 10781720 | E38: Profesional de logística y compra | F38: https://drive.google.com/drive/folders/1ybyXigCKCKVuRd9FwMoXDtVzicMEqByp | G38: 3053245763 | H38: 1 | I38: Córdoba | J38: Ciénaga de oro | K38: RCE_260102_5 | M38: 46035 | N38: Sí | O38: Equipo Nacional | P38: Sí | Q38: Activo | S38: RCE_260102_5
A39: 11003600 | B39: 46020 | C39: OBER CONTRERAS BENITEZ | D39: 11003600 | E39: Gestor | F39: https://drive.google.com/drive/folders/1Ly4GCHjKnAr9oR_LkFNkxGgYt-fuNGu- | G39: 3184628449 | H39: 1 | I39: Córdoba | J39: Montería | K39: RCE_260106_10 | L39: RCE_260102_3 | M39: 46035 | N39: Sí | O39: Equipo Técnico Territorial | P39: Sí | Q39: Activo | S39: RCE_260106_10
A40: 11039803 | B40: 46062 | C40: Jairo Javier Anaya Barrios | D40: 11039803 | E40: Gestor | F40: https://drive.google.com/drive/folders/1A6nTtO0eeVcptNhDbO-FDBmYyJzBklJ8?usp=sharing | G40: 3143807141 - 3127935094 | H40: 5 | I40: Antioquia | J40: El Bagre | L40: RCE_260213_52 | N40: No | O40: Equipo Técnico Territorial | P40: No
...

Sheet Cambio de roles
A1: Nombre completo | B1: Numero de cedula | C1: Cargo | D1: Enlace documentacion | E1: Celular | F1: Región | G1: Departamento | H1: Municipio | I1: Respuesta aprobación | J1: NO aprobados | K1: Fecha de envío a Prosperidad | L1: Aprobación | M1: Equipo Nacional/Regional | N1: Contratado | O1: Estatus | P1: Observaciones Validación de BD | Q1: Validar | R1: Validar
A2: JERSON STIVEN GARCIA PICON | B2: 1098812449 | C2: Profesional de logística y compra | D2: https://drive.google.com/drive/folders/1g2UZ9p3ff192jGokvNBKV2UmCrPWoozy | E2: 3112637825 | F2: 3 | G2: Santander | H2: Bucaramanga | I2: RCE_260318_76 | J2: RCE_260109_12 | K2: 46035 | L2: Sí | M2: Equipo Nacional | N2: No | O2: No Aprobado
A3: JERSON STIVEN GARCIA PICON | B3: 1098812449 | C3: PROFESIONAL DE SEGUIMIENTO E INFORMACIÓN | D3: https://drive.google.com/drive/folders/1g2UZ9p3ff192jGokvNBKV2UmCrPWoozy | F3: 3 | I3: RCE_260523_97 | K3: 46165 | L3: SI
A4: KARINA OVALLE MUEGUES | B4: 56096742 | C4: Profesional Tallerista | D4: https://drive.google.com/drive/folders/1EqVuSVrQ8kHn3pBeu_um2aEBWukgwsUD?usp=sharing | E4: 3217761167 | F4: 1 | G4: Cesar | H4: Valledupar | I4: RCE_260217_55 | L4: Sí | M4: Equipo Técnico Territorial | N4: No
A5: KARINA OVALLE MUEGUES | B5: 56096742 | C5: GESTOR | D5: https://drive.google.com/drive/folders/1B2Psekhu1jgtEOU-CYzs3z_Q_0PlKstw?usp=sharing | E5: 3217761167 | F5: 1 | I5: RCE_260521_96 | K5: 46163 | L5: SI
A6: RIKY ANDRES CARRILLO CADENA | B6: 1102724007 | C6: Profesional de Seguimiento e Información | D6: https://drive.google.com/drive/folders/1RQBfRYdZzXEYs-tGHykN4pt5FjItF8-Z | E6: 3132747639 | F6: 4 | G6: Bogotá | H6: Bogotá | J6: RCE_260105_7 RCE_260109_12 RCE_260408_79 | K6: 46035 | L6: No | M6: Equipo Nacional | N6: No | O6: No Aprobado
A7: Riky Andrés Carrillo Cadena | B7: 1102724007 | C7: Profesional de logística y compra | D7: https://drive.google.com/drive/folders/1RQBfRYdZzXEYs-tGHykN4pt5FjItF8-Z?usp=sharing | E7: 3132747639 | F7: 4 | G7: Bogotá | H7: Bogotá | I7: RCE_260410_81 | K7: 46035 | L7: Sí | M7: Equipo Nacional | N7: No

Sheet TD
A3: Etiquetas de fila | B3: Cuenta de Respuesta aprobación | C3: Cuenta de NO aprobados | E3: Rol | F3: Cantidad
A4: Coordinador General Regional | B4: 5 | C4: 1 | E4: Coordinación General Regional - 1 por región | F4: 5
A5: 1 | B5: 1
A6: 3 | B6: 1
A7: 4 | B7: 2
A8: 5 | B8: 1 | C8: 1
A9: Coordinador Local Regional | B9: 14 | C9: 5 | E9: Coordinadores locales regionales (2 por región) | F9: 10
A10: 1 | B10: 3
A11: 3 | B11: 1
A12: 4 | B12: 8 | C12: 4
A13: 5 | B13: 2 | C13: 1
A14: Gestor | B14: 260 | C14: 43 | E14: Gestores | F14: =165+18 -> 183
A15: 1 | B15: 44 | C15: 8
A16: 2 | B16: 29 | C16: 6
A17: 3 | B17: 31 | C17: 4
A18: 4 | B18: 88 | C18: 12
A19: 5 | B19: 68 | C19: 13
A20: Profesional Administrativo y Financiero | B20: 5 | E20: Profesional Administrativo y Financiero - 1 por región | F20: 5
A21: 1 | B21: 1
A22: 2 | B22: 1
A23: 3 | B23: 1
A24: 4 | B24: 2
A25: Profesional de Alianzas y Conexión a Mercados | B25: 8 | C25: 3 | E25: Profesional alianzas y conexión a mercados - 1 por región | F25: 5
A26: 1 | C26: 2
A27: 2 | B27: 2
A28: 3 | B28: 1
A29: 4 | B29: 5 | C29: 1
A30: Profesional de logística y compra | B30: 34 | C30: 7 | E30: Profesional de Logística y compra - 5 por región | F30: =25+10 -> 35
A31: 1 | B31: 6
A32: 2 | B32: 2 | C32: 1
A33: 3 | B33: 7 | C33: 2
A34: 4 | B34: 16 | C34: 4
A35: 5 | B35: 3
A36: Profesional de Seguimiento e Información | B36: 9 | C36: 5 | E36: Profesional de seguimiento e información - 1 por región | F36: 5
A37: 1 | B37: 1
A38: 3 | B38: 2 | C38: 3
A39: 4 | B39: 5 | C39: 2
A40: 5 | B40: 1
A41: Profesional Tallerista | B41: 116 | C41: 45 | E41: Profesional tallerista | F41: =65+2 -> 67
A42: 1 | B42: 22 | C42: 7
...

Sheet Equipo aprobado UdeA
A1: EQUIPO NACIONAL | B1: HV Aprobadas Interventoría- Enviadas Prosperidad | H1: Avance HV | I1: Meta Anexo Técnico
B2: 46035 | C2: 46039 | D2: 46043 | E2: 46049 | F2: 46057
A3: Coordinador General Regional | B3: =COUNTIFS(#REF!,'Equipo aprobado UdeA'!$B$2,#REF!,'Equipo aprobado UdeA'!A3,#REF!,"<>") -> #REF! | C3: =COUNTIFS(#REF!,'Equipo aprobado UdeA'!$C$2,#REF!,'Equipo aprobado UdeA'!A3,#REF!,"<>") -> #REF! | D3: =COUNTIFS(#REF!,'Equipo aprobado UdeA'!$D$2,#REF!,'Equipo aprobado UdeA'!A3,#REF!,"<>") -> #REF! | E3: =COUNTIFS(#REF!,'Equipo aprobado UdeA'!$E$2,#REF!,'Equipo aprobado UdeA'!A3,#REF!,"<>") -> #REF! | F3: =COUNTIFS(#REF!,'Equipo aprobado UdeA'!$F$2,#REF!,'Equipo aprobado UdeA'!A3,#REF!,"<>") -> #REF! | G3: =COUNTIFS(#REF!,$G$2,#REF!,'Equipo aprobado UdeA'!A3,#REF!,"<>") -> #REF! | H3: =SUM(B3:G3) -> #REF! | I3: 5 | J3: Equipo Nacional
A4: Profesional de Seguimiento e Información | B4: =COUNTIFS(#REF!,'Equipo aprobado UdeA'!$B$2,#REF!,'Equipo aprobado UdeA'!A4,#REF!,"<>") -> #REF! | C4: =COUNTIFS(#REF!,'Equipo aprobado UdeA'!$C$2,#REF!,'Equipo aprobado UdeA'!A4,#REF!,"<>") -> #REF! | D4: =COUNTIFS(#REF!,'Equipo aprobado UdeA'!$D$2,#REF!,'Equipo aprobado UdeA'!A4,#REF!,"<>") -> #REF! | E4: =COUNTIFS(#REF!,'Equipo aprobado UdeA'!$E$2,#REF!,'Equipo aprobado UdeA'!A4,#REF!,"<>") -> #REF! | F4: =COUNTIFS(#REF!,'Equipo aprobado UdeA'!$F$2,#REF!,'Equipo aprobado UdeA'!A4,#REF!,"<>") -> #REF! | G4: =COUNTIFS(#REF!,$G$2,#REF!,'Equipo aprobado UdeA'!A4,#REF!,"<>") -> #REF! | H4: =SUM(B4:G4) -> #REF! | I4: 5 | J4: Equipo Nacional
A5: Profesional de Alianzas y Conexión a Mercados | B5: =COUNTIFS(#REF!,'Equipo aprobado UdeA'!$B$2,#REF!,'Equipo aprobado UdeA'!A5,#REF!,"<>") -> #REF! | C5: =COUNTIFS(#REF!,'Equipo aprobado UdeA'!$C$2,#REF!,'Equipo aprobado UdeA'!A5,#REF!,"<>") -> #REF! | D5: =COUNTIFS(#REF!,'Equipo aprobado UdeA'!$D$2,#REF!,'Equipo aprobado UdeA'!A5,#REF!,"<>") -> #REF! | E5: =COUNTIFS(#REF!,'Equipo aprobado UdeA'!$E$2,#REF!,'Equipo aprobado UdeA'!A5,#REF!,"<>") -> #REF! | F5: =COUNTIFS(#REF!,'Equipo aprobado UdeA'!$F$2,#REF!,'Equipo aprobado UdeA'!A5,#REF!,"<>") -> #REF! | G5: =COUNTIFS(#REF!,$G$2,#REF!,'Equipo aprobado UdeA'!A5,#REF!,"<>") -> #REF! | H5: =SUM(B5:G5) -> #REF! | I5: 5 | J5: Equipo Nacional
A6: Profesional Administrativo y Financiero | B6: =COUNTIFS(#REF!,'Equipo aprobado UdeA'!$B$2,#REF!,'Equipo aprobado UdeA'!A6,#REF!,"<>") -> #REF! | C6: =COUNTIFS(#REF!,'Equipo aprobado UdeA'!$C$2,#REF!,'Equipo aprobado UdeA'!A6,#REF!,"<>") -> #REF! | D6: =COUNTIFS(#REF!,'Equipo aprobado UdeA'!$D$2,#REF!,'Equipo aprobado UdeA'!A6,#REF!,"<>") -> #REF! | E6: =COUNTIFS(#REF!,'Equipo aprobado UdeA'!$E$2,#REF!,'Equipo aprobado UdeA'!A6,#REF!,"<>") -> #REF! | F6: =COUNTIFS(#REF!,'Equipo aprobado UdeA'!$F$2,#REF!,'Equipo aprobado UdeA'!A6,#REF!,"<>") -> #REF! | G6: =COUNTIFS(#REF!,$G$2,#REF!,'Equipo aprobado UdeA'!A6,#REF!,"<>") -> #REF! | H6: =SUM(B6:G6) -> #REF! | I6: 5 | J6: Equipo Nacional
A7: Técnico Administrativo Regional de Apoyo | B7: =COUNTIFS(#REF!,'Equipo aprobado UdeA'!$B$2,#REF!,'Equipo aprobado UdeA'!A7,#REF!,"<>") -> #REF! | C7: =COUNTIFS(#REF!,'Equipo aprobado UdeA'!$C$2,#REF!,'Equipo aprobado UdeA'!A7,#REF!,"<>") -> #REF! | D7: =COUNTIFS(#REF!,'Equipo aprobado UdeA'!$D$2,#REF!,'Equipo aprobado UdeA'!A7,#REF!,"<>") -> #REF! | E7: =COUNTIFS(#REF!,'Equipo aprobado UdeA'!$E$2,#REF!,'Equipo aprobado UdeA'!A7,#REF!,"<>") -> #REF! | F7: =COUNTIFS(#REF!,'Equipo aprobado UdeA'!$F$2,#REF!,'Equipo aprobado UdeA'!A7,#REF!,"<>") -> #REF! | G7: =COUNTIFS(#REF!,$G$2,#REF!,'Equipo aprobado UdeA'!A7,#REF!,"<>") -> #REF! | H7: =SUM(B7:G7) -> #REF! | I7: 15 | J7: Equipo Nacional
A8: Profesional de Logística y Compra | B8: =COUNTIFS(#REF!,'Equipo aprobado UdeA'!$B$2,#REF!,'Equipo aprobado UdeA'!A8,#REF!,"<>") -> #REF! | C8: =COUNTIFS(#REF!,'Equipo aprobado UdeA'!$C$2,#REF!,'Equipo aprobado UdeA'!A8,#REF!,"<>") -> #REF! | D8: =COUNTIFS(#REF!,'Equipo aprobado UdeA'!$D$2,#REF!,'Equipo aprobado UdeA'!A8,#REF!,"<>") -> #REF! | E8: =COUNTIFS(#REF!,'Equipo aprobado UdeA'!$E$2,#REF!,'Equipo aprobado UdeA'!A8,#REF!,"<>") -> #REF! | F8: =COUNTIFS(#REF!,'Equipo aprobado UdeA'!$F$2,#REF!,'Equipo aprobado UdeA'!A8,#REF!,"<>") -> #REF! | G8: =COUNTIFS(#REF!,$G$2,#REF!,'Equipo aprobado UdeA'!A8,#REF!,"<>") -> #REF! | H8: =SUM(B8:G8) -> #REF! | I8: 25 | J8: Equipo Nacional
A9: HV No Aprobadas | B9: =COUNTIFS(#REF!,'Equipo aprobado UdeA'!$B$2,#REF!,'Equipo aprobado UdeA'!A1,#REF!,"") -> #REF! | C9: =COUNTIFS(#REF!,'Equipo aprobado UdeA'!$C$2,#REF!,'Equipo aprobado UdeA'!A1,#REF!,"") -> #REF! | D9: =COUNTIFS(#REF!,'Equipo aprobado UdeA'!$D$2,#REF!,'Equipo aprobado UdeA'!A1,#REF!,"") -> #REF! | E9: =COUNTIFS(#REF!,'Equipo aprobado UdeA'!$E$2,#REF!,'Equipo aprobado UdeA'!A1,#REF!,"") -> #REF! | F9: =COUNTIFS(#REF!,'Equipo aprobado UdeA'!$F$2,#REF!,'Equipo aprobado UdeA'!A1,#REF!,"") -> #REF! | G9: =COUNTIFS(#REF!,'Equipo aprobado UdeA'!$G$2,#REF!,'Equipo aprobado UdeA'!A1,#REF!,"") -> #REF! | H9: =SUM(B9:G9) -> #REF!
A10: TOTAL HV APROBADAS | B10: =SUM(B3:B8) -> #REF! | C10: =SUM(C3:C8) -> #REF! | D10: =SUM(D3:D8) -> #REF! | E10: =SUM(E3:E8) -> #REF! | F10: =SUM(F3:F8) -> #REF! | G10: =SUM(G3:G8) -> #REF! | H10: =SUM(H3:H8) -> #REF! | I10: =SUM(I3:I8) -> 60
B11: =B10/$I$10 -> #REF! | C11: =C10/$I$10 -> #REF! | D11: =D10/$I$10 -> #REF! | E11: =E10/$I$10 -> #REF! | F11: =F10/$I$10 -> #REF! | G11: =G10/$I$10 -> #REF! | H11: =H10/$I$10 -> #REF!
A13: EQUIPO TÉCNICO TERRITORIAL | B13: HV Aprobadas Interventoría- Enviadas Prosperidad | H13: Avance HV | I13: Anexo Técnico
B14: =B2 -> 46035 | C14: =C2 -> 46039 | D14: =D2 -> 46043 | E14: =E2 -> 46049 | F14: =F2 -> 46057 | G14: =G2 -> 0
A15: Coordinador Local Regional | B15: =COUNTIFS(#REF!,'Equipo aprobado UdeA'!$B$14,#REF!,'Equipo aprobado UdeA'!A15,#REF!,"<>") -> #REF! | C15: =COUNTIFS(#REF!,'Equipo aprobado UdeA'!$C$14,#REF!,'Equipo aprobado UdeA'!A15,#REF!,"<>") -> #REF! | D15: =COUNTIFS(#REF!,'Equipo aprobado UdeA'!$D$14,#REF!,'Equipo aprobado UdeA'!A15,#REF!,"<>") -> #REF! | E15: =COUNTIFS(#REF!,'Equipo aprobado UdeA'!$E$14,#REF!,'Equipo aprobado UdeA'!A15,#REF!,"<>") -> #REF! | F15: =COUNTIFS(#REF!,'Equipo aprobado UdeA'!$F$14,#REF!,'Equipo aprobado UdeA'!A15,#REF!,"<>") -> #REF! | G15: =COUNTIFS(#REF!,'Equipo aprobado UdeA'!$G$14,#REF!,'Equipo aprobado UdeA'!A15,#REF!,"<>") -> #REF! | H15: =SUM(B15:G15) -> #REF! | I15: 10 | J15: Equipo Técnico Territorial
A16: Gestor | B16: =COUNTIFS(#REF!,'Equipo aprobado UdeA'!$B$14,#REF!,'Equipo aprobado UdeA'!A16,#REF!,"<>") -> #REF! | C16: =COUNTIFS(#REF!,'Equipo aprobado UdeA'!$C$14,#REF!,'Equipo aprobado UdeA'!A16,#REF!,"<>") -> #REF! | D16: =COUNTIFS(#REF!,'Equipo aprobado UdeA'!$D$14,#REF!,'Equipo aprobado UdeA'!A16,#REF!,"<>") -> #REF! | E16: =COUNTIFS(#REF!,'Equipo aprobado UdeA'!$E$14,#REF!,'Equipo aprobado UdeA'!A16,#REF!,"<>") -> #REF! | F16: =COUNTIFS(#REF!,'Equipo aprobado UdeA'!$F$14,#REF!,'Equipo aprobado UdeA'!A16,#REF!,"<>") -> #REF! | G16: =COUNTIFS(#REF!,'Equipo aprobado UdeA'!$G$14,#REF!,'Equipo aprobado UdeA'!A16,#REF!,"<>") -> #REF! | H16: =SUM(B16:G16) -> #REF! | I16: 165 | J16: Equipo Técnico Territorial
A17: Profesional Tallerista | B17: =COUNTIFS(#REF!,'Equipo aprobado UdeA'!$B$14,#REF!,'Equipo aprobado UdeA'!A17,#REF!,"<>") -> #REF! | C17: =COUNTIFS(#REF!,'Equipo aprobado UdeA'!$C$14,#REF!,'Equipo aprobado UdeA'!A17,#REF!,"<>") -> #REF! | D17: =COUNTIFS(#REF!,'Equipo aprobado UdeA'!$D$14,#REF!,'Equipo aprobado UdeA'!A17,#REF!,"<>") -> #REF! | E17: =COUNTIFS(#REF!,'Equipo aprobado UdeA'!$E$14,#REF!,'Equipo aprobado UdeA'!A17,#REF!,"<>") -> #REF! | F17: =COUNTIFS(#REF!,'Equipo aprobado UdeA'!$F$14,#REF!,'Equipo aprobado UdeA'!A17,#REF!,"<>") -> #REF! | G17: =COUNTIFS(#REF!,'Equipo aprobado UdeA'!$G$14,#REF!,'Equipo aprobado UdeA'!A17,#REF!,"<>") -> #REF! | H17: =SUM(B17:G17) -> #REF! | I17: 65 | J17: Equipo Técnico Territorial
A18: HV No Aprobadas | B18: =COUNTIFS(#REF!,'Equipo aprobado UdeA'!$B$14,#REF!,'Equipo aprobado UdeA'!A13,#REF!,"") -> #REF! | C18: =COUNTIFS(#REF!,'Equipo aprobado UdeA'!$C$14,#REF!,'Equipo aprobado UdeA'!A13,#REF!,"") -> #REF! | D18: =COUNTIFS(#REF!,'Equipo aprobado UdeA'!$D$14,#REF!,'Equipo aprobado UdeA'!A13,#REF!,"") -> #REF! | E18: =COUNTIFS(#REF!,'Equipo aprobado UdeA'!$E$14,#REF!,'Equipo aprobado UdeA'!A13,#REF!,"") -> #REF! | F18: =COUNTIFS(#REF!,'Equipo aprobado UdeA'!$F$14,#REF!,'Equipo aprobado UdeA'!A13,#REF!,"") -> #REF! | G18: =COUNTIFS(#REF!,'Equipo aprobado UdeA'!$G$14,#REF!,'Equipo aprobado UdeA'!A13,#REF!,"") -> #REF! | H18: =SUM(B18:G18) -> #REF!
A19: TOTAL HV APROBADAS | B19: =SUM(B15:B17) -> #REF! | C19: =SUM(C15:C17) -> #REF! | D19: =SUM(D15:D17) -> #REF! | E19: =SUM(E15:E17) -> #REF! | F19: =SUM(F15:F17) -> #REF! | G19: =SUM(G15:G17) -> #REF! | H19: =SUM(H15:H17) -> #REF! | I19: =SUM(I15:I17) -> 240
B20: =B19/$I$19 -> #REF! | C20: =C19/$I$19 -> #REF! | D20: =D19/$I$19 -> #REF! | E20: =E19/$I$19 -> #REF! | F20: =F19/$I$19 -> #REF! | G20: =G19/$I$19 -> #REF! | H20: =H19/$I$19 -> #REF!
J22: =H10+H19 -> #REF!
J23: =H9+H18 -> #REF!
J24: =SUM(J22:J23) -> #REF!

Sheet Hoja1
B1: Cargo | D1: Contratado
B2: Coordinador General Regional | D2: Sí
B3: Coordinador Local Regional | D3: No
B4: Gestor
B5: Profesional Administrativo y Financiero
B6: Profesional de Alianzas y Conexión a Mercados
B7: Profesional de logística y compra
B8: Profesional de Seguimiento e Información
B9: Profesional Tallerista
B10: Técnico Administrativo Regional de Apoyo
